{
  "version": 8,
  "blockIdVersion": 11,
  "anchorX": 0,
  "anchorY": 0,
  "anchorZ": 0,
  "blocks": [
    {
      "x": -19,
      "y": 5,
      "z": 11,
      "name": "Plant_Leaves_Poisoned_Red_Walkable",
      "rotation": 3
    },
    {
      "x": -19,
      "y": 6,
      "z": 11,
      "name": "Plant_Leaves_Poisoned_Red_Walkable",
      "rotation": 3
    },
    {
      "x": -19,
      "y": 7,
      "z": 11,
      "name": "Plant_Moss_Rug_Red_Placeable",
      "rotation": 3
    },
    {
      "x": -19,
      "y": 6,
      "z": 12,
      "name": "Plant_Leaves_Poisoned_Red_Walkable",
      "rotation": 3
    },
    {
      "x": -19,
      "y": 7,
      "z": 12,
      "name": "Plant_Moss_Rug_Red_Placeable",
      "rotation": 3
    },
    {
      "x": -18,
      "y": 4,
      "z": 10,
      "name": "Plant_Leaves_Poisoned_Red_Walkable",
      "rotation": 3
    },
    {
      "x": -18,
      "y": 5,
      "z": 10,
      "name": "Plant_Moss_Rug_Red_Placeable",
      "rotation": 3
    },
    {
      "x": -18,
      "y": 4,
      "z": 11,
      "name": "Plant_Leaves_Poisoned_Red_Walkable",
      "rotation": 3
    },
    {
      "x": -18,
      "y": 5,
      "z": 11,
      "name": "Plant_Leaves_Poisoned_Red_Walkable",
      "rotation": 3
    },
    {
      "x": -18,
      "y": 5,
      "z": 12,
      "name": "Plant_Leaves_Poisoned_Red_Walkable",
      "rotation": 3
    },
    {
      "x": -18,
      "y": 6,
      "z": 12,
      "name": "Plant_Moss_Rug_Red_Placeable",
      "rotation": 3
    },
    {
      "x": -17,
      "y": 3,
      "z": 10,
      "name": "Plant_Leaves_Poisoned_Red_Walkable",
      "rotation": 3
    },
    {
      "x": -17,
      "y": 4,
      "z": 11,
      "name": "Plant_Leaves_Poisoned_Red_Walkable",
      "rotation": 3
    },
    {
      "x": -17,
      "y": 5,
      "z": 11,
      "name": "Plant_Moss_Rug_Red_Placeable",
      "rotation": 3
    },
    {
      "x": -16,
      "y": 3,
      "z": 9,
      "name": "Plant_Leaves_Poisoned_Red_Walkable",
      "rotation": 3
    },
    {
      "x": -16,
      "y": 3,
      "z": 10,
      "name": "Plant_Leaves_Poisoned_Red_Walkable",
      "rotation": 3
    },
    {
      "x": -16,
      "y": 4,
      "z": 10,
      "name": "Plant_Moss_Rug_Red_Placeable",
      "rotation": 3
    },
    {
      "x": -16,
      "y": 3,
      "z": 11,
      "name": "Plant_Leaves_Poisoned_Red_Walkable",
      "rotation": 3
    },
    {
      "x": -15,
      "y": 2,
      "z": 9,
      "name": "Plant_Leaves_Poisoned_Red_Walkable",
      "rotation": 3
    },
    {
      "x": -15,
      "y": 2,
      "z": 10,
      "name": "Plant_Leaves_Poisoned_Red_Walkable",
      "rotation": 3
    },
    {
      "x": -14,
      "y": 1,
      "z": 8,
      "name": "Plant_Leaves_Poisoned_Red_Walkable",
      "rotation": 3
    },
    {
      "x": -14,
      "y": 1,
      "z": 9,
      "name": "Plant_Leaves_Poisoned_Red_Walkable",
      "rotation": 3
    },
    {
      "x": -14,
      "y": 2,
      "z": 9,
      "name": "Plant_Moss_Rug_Red_Placeable",
      "rotation": 3
    },
    {
      "x": -13,
      "y": 0,
      "z": 7,
      "name": "Plant_Leaves_Poisoned_Red_Walkable",
      "rotation": 3
    },
    {
      "x": -13,
      "y": 1,
      "z": 7,
      "name": "Plant_Moss_Rug_Red_Placeable",
      "rotation": 3
    },
    {
      "x": -13,
      "y": 0,
      "z": 8,
      "name": "Plant_Leaves_Poisoned_Red_Walkable",
      "rotation": 3
    },
    {
      "x": -13,
      "y": 1,
      "z": 8,
      "name": "Plant_Moss_Rug_Red_Placeable",
      "rotation": 3
    },
    {
      "x": -13,
      "y": 0,
      "z": 9,
      "name": "Plant_Leaves_Poisoned_Red_Walkable",
      "rotation": 3
    },
    {
      "x": -12,
      "y": -1,
      "z": 7,
      "name": "Plant_Leaves_Poisoned_Red_Walkable",
      "rotation": 3
    },
    {
      "x": -12,
      "y": 0,
      "z": 8,
      "name": "Plant_Leaves_Poisoned_Red_Walkable",
      "rotation": 3
    },
    {
      "x": -11,
      "y": -1,
      "z": 6,
      "name": "Plant_Leaves_Poisoned_Red_Walkable",
      "rotation": 3
    },
    {
      "x": -11,
      "y": 0,
      "z": 6,
      "name": "Plant_Moss_Rug_Red_Placeable",
      "rotation": 3
    },
    {
      "x": -11,
      "y": -1,
      "z": 7,
      "name": "Plant_Leaves_Poisoned_Red_Walkable",
      "rotation": 3
    },
    {
      "x": -11,
      "y": -1,
      "z": 8,
      "name": "Plant_Leaves_Poisoned_Red_Walkable",
      "rotation": 3
    },
    {
      "x": -10,
      "y": -2,
      "z": 6,
      "name": "Plant_Leaves_Poisoned_Red_Walkable",
      "rotation": 3
    },
    {
      "x": -10,
      "y": -1,
      "z": 7,
      "name": "Plant_Leaves_Poisoned_Red_Walkable",
      "rotation": 3
    },
    {
      "x": -9,
      "y": -2,
      "z": 5,
      "name": "Plant_Leaves_Poisoned_Red_Walkable",
      "rotation": 3
    },
    {
      "x": -9,
      "y": -2,
      "z": 6,
      "name": "Plant_Leaves_Poisoned_Red_Walkable",
      "rotation": 3
    },
    {
      "x": -9,
      "y": -1,
      "z": 6,
      "name": "Plant_Moss_Rug_Red_Placeable",
      "rotation": 3
    },
    {
      "x": -9,
      "y": -2,
      "z": 7,
      "name": "Plant_Leaves_Poisoned_Red_Walkable",
      "rotation": 3
    },
    {
      "x": -8,
      "y": -2,
      "z": 5,
      "name": "Plant_Leaves_Poisoned_Red_Walkable",
      "rotation": 3
    },
    {
      "x": -8,
      "y": -1,
      "z": 5,
      "name": "Plant_Moss_Rug_Red_Placeable",
      "rotation": 3
    },
    {
      "x": -8,
      "y": -2,
      "z": 6,
      "name": "Plant_Leaves_Poisoned_Red_Walkable",
      "rotation": 3
    },
    {
      "x": -8,
      "y": -1,
      "z": 6,
      "name": "Plant_Moss_Rug_Red_Placeable",
      "rotation": 3
    },
    {
      "x": -7,
      "y": -2,
      "z": 4,
      "name": "Plant_Leaves_Poisoned_Red_Walkable",
      "rotation": 3
    },
    {
      "x": -7,
      "y": -1,
      "z": 4,
      "name": "Plant_Moss_Rug_Red_Placeable",
      "rotation": 3
    },
    {
      "x": -7,
      "y": -2,
      "z": 5,
      "name": "Plant_Leaves_Poisoned_Red_Walkable",
      "rotation": 3
    },
    {
      "x": -7,
      "y": -1,
      "z": 5,
      "name": "Plant_Moss_Rug_Red_Placeable",
      "rotation": 3
    },
    {
      "x": -7,
      "y": -2,
      "z": 6,
      "name": "Plant_Leaves_Poisoned_Red_Walkable",
      "rotation": 3
    },
    {
      "x": -6,
      "y": -2,
      "z": 3,
      "name": "Plant_Leaves_Poisoned_Red_Walkable",
      "rotation": 3
    },
    {
      "x": -6,
      "y": -2,
      "z": 4,
      "name": "Plant_Leaves_Poisoned_Red_Walkable",
      "rotation": 3
    },
    {
      "x": -6,
      "y": -2,
      "z": 5,
      "name": "Plant_Leaves_Poisoned_Red_Walkable",
      "rotation": 3
    },
    {
      "x": -6,
      "y": -1,
      "z": 5,
      "name": "Plant_Moss_Rug_Red_Placeable",
      "rotation": 3
    },
    {
      "x": -5,
      "y": -1,
      "z": 3,
      "name": "Plant_Leaves_Poisoned_Red_Walkable",
      "rotation": 3
    },
    {
      "x": -5,
      "y": 0,
      "z": 3,
      "name": "Plant_Moss_Rug_Red_Placeable",
      "rotation": 3
    },
    {
      "x": -5,
      "y": -2,
      "z": 4,
      "name": "Plant_Leaves_Poisoned_Red_Walkable",
      "rotation": 3
    },
    {
      "x": -5,
      "y": -1,
      "z": 4,
      "name": "Plant_Moss_Rug_Red_Placeable",
      "rotation": 3
    },
    {
      "x": -4,
      "y": -1,
      "z": 2,
      "name": "Plant_Leaves_Poisoned_Red_Walkable",
      "rotation": 3
    },
    {
      "x": -4,
      "y": 0,
      "z": 2,
      "name": "Plant_Moss_Rug_Red_Placeable",
      "rotation": 3
    },
    {
      "x": -4,
      "y": -1,
      "z": 3,
      "name": "Plant_Leaves_Poisoned_Red_Walkable",
      "rotation": 3
    },
    {
      "x": -4,
      "y": 0,
      "z": 3,
      "name": "Plant_Moss_Rug_Red_Placeable",
      "rotation": 3
    },
    {
      "x": -4,
      "y": -1,
      "z": 4,
      "name": "Plant_Leaves_Poisoned_Red_Walkable",
      "rotation": 3
    },
    {
      "x": -3,
      "y": 0,
      "z": 2,
      "name": "Plant_Leaves_Poisoned_Red_Walkable",
      "rotation": 3
    },
    {
      "x": -3,
      "y": -1,
      "z": 3,
      "name": "Plant_Leaves_Poisoned_Red_Walkable",
      "rotation": 3
    },
    {
      "x": -3,
      "y": 0,
      "z": 3,
      "name": "Plant_Leaves_Poisoned_Red_Walkable",
      "rotation": 3
    },
    {
      "x": -2,
      "y": 0,
      "z": 1,
      "name": "Plant_Leaves_Poisoned_Red_Walkable",
      "rotation": 3
    },
    {
      "x": -2,
      "y": 1,
      "z": 1,
      "name": "Plant_Moss_Rug_Red_Placeable",
      "rotation": 3
    },
    {
      "x": -2,
      "y": 0,
      "z": 2,
      "name": "Plant_Leaves_Poisoned_Red_Walkable",
      "rotation": 3
    },
    {
      "x": -2,
      "y": 0,
      "z": 3,
      "name": "Plant_Leaves_Poisoned_Red_Walkable",
      "rotation": 3
    },
    {
      "x": -1,
      "y": 1,
      "z": 1,
      "name": "Plant_Leaves_Poisoned_Red_Walkable",
      "rotation": 3
    },
    {
      "x": -1,
      "y": 2,
      "z": 1,
      "name": "Plant_Moss_Rug_Red_Placeable",
      "rotation": 3
    },
    {
      "x": -1,
      "y": 1,
      "z": 2,
      "name": "Plant_Leaves_Poisoned_Red_Walkable",
      "rotation": 3
    },
    {
      "x": -1,
      "y": 2,
      "z": 2,
      "name": "Plant_Moss_Rug_Red_Placeable",
      "rotation": 3
    },
    {
      "x": 0,
      "y": 1,
      "z": 0,
      "name": "Plant_Leaves_Poisoned_Red_Walkable",
      "rotation": 3
    },
    {
      "x": 0,
      "y": 2,
      "z": 0,
      "name": "Plant_Moss_Rug_Red_Placeable",
      "rotation": 3
    },
    {
      "x": 0,
      "y": 1,
      "z": 1,
      "name": "Plant_Leaves_Poisoned_Red_Walkable",
      "rotation": 3
    },
    {
      "x": 0,
      "y": 2,
      "z": 1,
      "name": "Plant_Moss_Rug_Red_Placeable",
      "rotation": 3
    }
  ]
}