{
  "version": 8,
  "blockIdVersion": 11,
  "anchorX": 0,
  "anchorY": 0,
  "anchorZ": 0,
  "blocks": [
    {
      "x": -39,
      "y": 7,
      "z": 22,
      "name": "Plant_Leaves_Poisoned_Red_Walkable",
      "rotation": 3
    },
    {
      "x": -39,
      "y": 8,
      "z": 22,
      "name": "Plant_Moss_Rug_Red_Placeable",
      "rotation": 3
    },
    {
      "x": -38,
      "y": 6,
      "z": 22,
      "name": "Plant_Leaves_Poisoned_Red_Walkable",
      "rotation": 3
    },
    {
      "x": -38,
      "y": 7,
      "z": 23,
      "name": "Plant_Leaves_Poisoned_Red_Walkable",
      "rotation": 3
    },
    {
      "x": -38,
      "y": 8,
      "z": 23,
      "name": "Plant_Moss_Rug_Red_Placeable",
      "rotation": 3
    },
    {
      "x": -37,
      "y": 5,
      "z": 21,
      "name": "Plant_Leaves_Poisoned_Red_Walkable",
      "rotation": 3
    },
    {
      "x": -37,
      "y": 6,
      "z": 21,
      "name": "Plant_Moss_Rug_Red_Placeable",
      "rotation": 3
    },
    {
      "x": -37,
      "y": 5,
      "z": 22,
      "name": "Plant_Leaves_Poisoned_Red_Walkable",
      "rotation": 3
    },
    {
      "x": -37,
      "y": 6,
      "z": 22,
      "name": "Plant_Leaves_Poisoned_Red_Walkable",
      "rotation": 3
    },
    {
      "x": -37,
      "y": 6,
      "z": 23,
      "name": "Plant_Leaves_Poisoned_Red_Walkable",
      "rotation": 3
    },
    {
      "x": -37,
      "y": 7,
      "z": 23,
      "name": "Plant_Moss_Rug_Red_Placeable",
      "rotation": 3
    },
    {
      "x": -36,
      "y": 4,
      "z": 21,
      "name": "Plant_Leaves_Poisoned_Red_Walkable",
      "rotation": 3
    },
    {
      "x": -36,
      "y": 5,
      "z": 21,
      "name": "Plant_Moss_Rug_Red_Placeable",
      "rotation": 3
    },
    {
      "x": -36,
      "y": 4,
      "z": 22,
      "name": "Plant_Leaves_Poisoned_Red_Walkable",
      "rotation": 3
    },
    {
      "x": -36,
      "y": 5,
      "z": 22,
      "name": "Plant_Moss_Rug_Red_Placeable",
      "rotation": 3
    },
    {
      "x": -35,
      "y": 3,
      "z": 20,
      "name": "Plant_Leaves_Poisoned_Red_Walkable",
      "rotation": 3
    },
    {
      "x": -35,
      "y": 3,
      "z": 21,
      "name": "Plant_Leaves_Poisoned_Red_Walkable",
      "rotation": 3
    },
    {
      "x": -35,
      "y": 4,
      "z": 21,
      "name": "Plant_Moss_Rug_Red_Placeable",
      "rotation": 3
    },
    {
      "x": -34,
      "y": 2,
      "z": 20,
      "name": "Plant_Leaves_Poisoned_Red_Walkable",
      "rotation": 3
    },
    {
      "x": -34,
      "y": 3,
      "z": 20,
      "name": "Plant_Moss_Rug_Red_Placeable",
      "rotation": 3
    },
    {
      "x": -34,
      "y": 2,
      "z": 21,
      "name": "Plant_Leaves_Poisoned_Red_Walkable",
      "rotation": 3
    },
    {
      "x": -34,
      "y": 3,
      "z": 21,
      "name": "Plant_Moss_Rug_Red_Placeable",
      "rotation": 3
    },
    {
      "x": -33,
      "y": 0,
      "z": 19,
      "name": "Plant_Leaves_Poisoned_Red_Walkable",
      "rotation": 3
    },
    {
      "x": -33,
      "y": 1,
      "z": 19,
      "name": "Plant_Moss_Rug_Red_Placeable",
      "rotation": 3
    },
    {
      "x": -33,
      "y": 2,
      "z": 19,
      "name": "Plant_Moss_Rug_Red_Placeable",
      "rotation": 3
    },
    {
      "x": -33,
      "y": 1,
      "z": 20,
      "name": "Plant_Leaves_Poisoned_Red_Walkable",
      "rotation": 3
    },
    {
      "x": -33,
      "y": 2,
      "z": 20,
      "name": "Plant_Moss_Rug_Red_Placeable",
      "rotation": 3
    },
    {
      "x": -32,
      "y": 0,
      "z": 18,
      "name": "Plant_Leaves_Poisoned_Red_Walkable",
      "rotation": 3
    },
    {
      "x": -32,
      "y": 0,
      "z": 19,
      "name": "Plant_Leaves_Poisoned_Red_Walkable",
      "rotation": 3
    },
    {
      "x": -32,
      "y": 0,
      "z": 20,
      "name": "Plant_Leaves_Poisoned_Red_Walkable",
      "rotation": 3
    },
    {
      "x": -31,
      "y": -1,
      "z": 18,
      "name": "Plant_Leaves_Poisoned_Red_Walkable",
      "rotation": 3
    },
    {
      "x": -31,
      "y": 0,
      "z": 19,
      "name": "Plant_Leaves_Poisoned_Red_Walkable",
      "rotation": 3
    },
    {
      "x": -30,
      "y": -2,
      "z": 17,
      "name": "Plant_Leaves_Poisoned_Red_Walkable",
      "rotation": 3
    },
    {
      "x": -30,
      "y": -1,
      "z": 17,
      "name": "Plant_Moss_Rug_Red_Placeable",
      "rotation": 3
    },
    {
      "x": -30,
      "y": -2,
      "z": 18,
      "name": "Plant_Leaves_Poisoned_Red_Walkable",
      "rotation": 3
    },
    {
      "x": -30,
      "y": -1,
      "z": 18,
      "name": "Plant_Moss_Rug_Red_Placeable",
      "rotation": 3
    },
    {
      "x": -30,
      "y": -1,
      "z": 19,
      "name": "Plant_Leaves_Poisoned_Red_Walkable",
      "rotation": 3
    },
    {
      "x": -30,
      "y": 0,
      "z": 19,
      "name": "Plant_Moss_Rug_Red_Placeable",
      "rotation": 3
    },
    {
      "x": -29,
      "y": -2,
      "z": 17,
      "name": "Plant_Leaves_Poisoned_Red_Walkable",
      "rotation": 3
    },
    {
      "x": -29,
      "y": -1,
      "z": 17,
      "name": "Plant_Moss_Rug_Red_Placeable",
      "rotation": 3
    },
    {
      "x": -29,
      "y": -2,
      "z": 18,
      "name": "Plant_Leaves_Poisoned_Red_Walkable",
      "rotation": 3
    },
    {
      "x": -29,
      "y": -1,
      "z": 18,
      "name": "Plant_Moss_Rug_Red_Placeable",
      "rotation": 3
    },
    {
      "x": -28,
      "y": -3,
      "z": 16,
      "name": "Plant_Leaves_Poisoned_Red_Walkable",
      "rotation": 3
    },
    {
      "x": -28,
      "y": -2,
      "z": 16,
      "name": "Plant_Moss_Rug_Red_Placeable",
      "rotation": 3
    },
    {
      "x": -28,
      "y": -3,
      "z": 17,
      "name": "Plant_Leaves_Poisoned_Red_Walkable",
      "rotation": 3
    },
    {
      "x": -27,
      "y": -4,
      "z": 15,
      "name": "Plant_Leaves_Poisoned_Red_Walkable",
      "rotation": 3
    },
    {
      "x": -27,
      "y": -4,
      "z": 16,
      "name": "Plant_Leaves_Poisoned_Red_Walkable",
      "rotation": 3
    },
    {
      "x": -27,
      "y": -3,
      "z": 16,
      "name": "Plant_Moss_Rug_Red_Placeable",
      "rotation": 3
    },
    {
      "x": -27,
      "y": -4,
      "z": 17,
      "name": "Plant_Leaves_Poisoned_Red_Walkable",
      "rotation": 3
    },
    {
      "x": -27,
      "y": -3,
      "z": 17,
      "name": "Plant_Moss_Rug_Red_Placeable",
      "rotation": 3
    },
    {
      "x": -26,
      "y": -5,
      "z": 15,
      "name": "Plant_Leaves_Poisoned_Red_Walkable",
      "rotation": 3
    },
    {
      "x": -26,
      "y": -4,
      "z": 15,
      "name": "Plant_Moss_Rug_Red_Placeable",
      "rotation": 3
    },
    {
      "x": -26,
      "y": -4,
      "z": 16,
      "name": "Plant_Leaves_Poisoned_Red_Walkable",
      "rotation": 3
    },
    {
      "x": -25,
      "y": -5,
      "z": 14,
      "name": "Plant_Leaves_Poisoned_Red_Walkable",
      "rotation": 3
    },
    {
      "x": -25,
      "y": -5,
      "z": 15,
      "name": "Plant_Leaves_Poisoned_Red_Walkable",
      "rotation": 3
    },
    {
      "x": -25,
      "y": -4,
      "z": 15,
      "name": "Plant_Moss_Rug_Red_Placeable",
      "rotation": 3
    },
    {
      "x": -25,
      "y": -5,
      "z": 16,
      "name": "Plant_Leaves_Poisoned_Red_Walkable",
      "rotation": 3
    },
    {
      "x": -24,
      "y": -6,
      "z": 14,
      "name": "Plant_Leaves_Poisoned_Red_Walkable",
      "rotation": 3
    },
    {
      "x": -24,
      "y": -5,
      "z": 14,
      "name": "Plant_Moss_Rug_Red_Placeable",
      "rotation": 3
    },
    {
      "x": -24,
      "y": -5,
      "z": 15,
      "name": "Plant_Leaves_Poisoned_Red_Walkable",
      "rotation": 3
    },
    {
      "x": -24,
      "y": -4,
      "z": 15,
      "name": "Plant_Moss_Rug_Red_Placeable",
      "rotation": 3
    },
    {
      "x": -23,
      "y": -6,
      "z": 13,
      "name": "Plant_Leaves_Poisoned_Red_Walkable",
      "rotation": 3
    },
    {
      "x": -23,
      "y": -6,
      "z": 14,
      "name": "Plant_Leaves_Poisoned_Red_Walkable",
      "rotation": 3
    },
    {
      "x": -23,
      "y": -6,
      "z": 15,
      "name": "Plant_Leaves_Poisoned_Red_Walkable",
      "rotation": 3
    },
    {
      "x": -23,
      "y": -5,
      "z": 15,
      "name": "Plant_Moss_Rug_Red_Placeable",
      "rotation": 3
    },
    {
      "x": -22,
      "y": -6,
      "z": 13,
      "name": "Plant_Leaves_Poisoned_Red_Walkable",
      "rotation": 3
    },
    {
      "x": -22,
      "y": -6,
      "z": 14,
      "name": "Plant_Leaves_Poisoned_Red_Walkable",
      "rotation": 3
    },
    {
      "x": -21,
      "y": -7,
      "z": 12,
      "name": "Plant_Leaves_Poisoned_Red_Walkable",
      "rotation": 3
    },
    {
      "x": -21,
      "y": -7,
      "z": 13,
      "name": "Plant_Leaves_Poisoned_Red_Walkable",
      "rotation": 3
    },
    {
      "x": -21,
      "y": -6,
      "z": 13,
      "name": "Plant_Moss_Rug_Red_Placeable",
      "rotation": 3
    },
    {
      "x": -20,
      "y": -7,
      "z": 11,
      "name": "Plant_Leaves_Poisoned_Red_Walkable",
      "rotation": 3
    },
    {
      "x": -20,
      "y": -6,
      "z": 11,
      "name": "Plant_Moss_Rug_Red_Placeable",
      "rotation": 3
    },
    {
      "x": -20,
      "y": -7,
      "z": 12,
      "name": "Plant_Leaves_Poisoned_Red_Walkable",
      "rotation": 3
    },
    {
      "x": -20,
      "y": -6,
      "z": 12,
      "name": "Plant_Moss_Rug_Red_Placeable",
      "rotation": 3
    },
    {
      "x": -20,
      "y": -7,
      "z": 13,
      "name": "Plant_Leaves_Poisoned_Red_Walkable",
      "rotation": 3
    },
    {
      "x": -20,
      "y": -6,
      "z": 13,
      "name": "Plant_Moss_Rug_Red_Placeable",
      "rotation": 3
    },
    {
      "x": -19,
      "y": -7,
      "z": 11,
      "name": "Plant_Leaves_Poisoned_Red_Walkable",
      "rotation": 3
    },
    {
      "x": -19,
      "y": -7,
      "z": 12,
      "name": "Plant_Leaves_Poisoned_Red_Walkable",
      "rotation": 3
    },
    {
      "x": -18,
      "y": -7,
      "z": 10,
      "name": "Plant_Leaves_Poisoned_Red_Walkable",
      "rotation": 3
    },
    {
      "x": -18,
      "y": -6,
      "z": 10,
      "name": "Plant_Moss_Rug_Red_Placeable",
      "rotation": 3
    },
    {
      "x": -18,
      "y": -7,
      "z": 11,
      "name": "Plant_Leaves_Poisoned_Red_Walkable",
      "rotation": 3
    },
    {
      "x": -18,
      "y": -6,
      "z": 11,
      "name": "Plant_Moss_Rug_Red_Placeable",
      "rotation": 3
    },
    {
      "x": -18,
      "y": -7,
      "z": 12,
      "name": "Plant_Leaves_Poisoned_Red_Walkable",
      "rotation": 3
    },
    {
      "x": -17,
      "y": -7,
      "z": 10,
      "name": "Plant_Leaves_Poisoned_Red_Walkable",
      "rotation": 3
    },
    {
      "x": -17,
      "y": -7,
      "z": 11,
      "name": "Plant_Leaves_Poisoned_Red_Walkable",
      "rotation": 3
    },
    {
      "x": -17,
      "y": -6,
      "z": 11,
      "name": "Plant_Moss_Rug_Red_Placeable",
      "rotation": 3
    },
    {
      "x": -16,
      "y": -8,
      "z": 9,
      "name": "Plant_Leaves_Poisoned_Red_Walkable",
      "rotation": 3
    },
    {
      "x": -16,
      "y": -8,
      "z": 10,
      "name": "Plant_Leaves_Poisoned_Red_Walkable",
      "rotation": 3
    },
    {
      "x": -16,
      "y": -7,
      "z": 10,
      "name": "Plant_Moss_Rug_Red_Placeable",
      "rotation": 3
    },
    {
      "x": -15,
      "y": -8,
      "z": 8,
      "name": "Plant_Leaves_Poisoned_Red_Walkable",
      "rotation": 3
    },
    {
      "x": -15,
      "y": -8,
      "z": 9,
      "name": "Plant_Leaves_Poisoned_Red_Walkable",
      "rotation": 3
    },
    {
      "x": -15,
      "y": -7,
      "z": 9,
      "name": "Plant_Moss_Rug_Red_Placeable",
      "rotation": 3
    },
    {
      "x": -15,
      "y": -8,
      "z": 10,
      "name": "Plant_Leaves_Poisoned_Red_Walkable",
      "rotation": 3
    },
    {
      "x": -14,
      "y": -8,
      "z": 8,
      "name": "Plant_Leaves_Poisoned_Red_Walkable",
      "rotation": 3
    },
    {
      "x": -14,
      "y": -8,
      "z": 9,
      "name": "Plant_Leaves_Poisoned_Red_Walkable",
      "rotation": 3
    },
    {
      "x": -13,
      "y": -8,
      "z": 7,
      "name": "Plant_Leaves_Poisoned_Red_Walkable",
      "rotation": 3
    },
    {
      "x": -13,
      "y": -7,
      "z": 7,
      "name": "Plant_Moss_Rug_Red_Placeable",
      "rotation": 3
    },
    {
      "x": -13,
      "y": -8,
      "z": 8,
      "name": "Plant_Leaves_Poisoned_Red_Walkable",
      "rotation": 3
    },
    {
      "x": -13,
      "y": -7,
      "z": 8,
      "name": "Plant_Moss_Rug_Red_Placeable",
      "rotation": 3
    },
    {
      "x": -13,
      "y": -8,
      "z": 9,
      "name": "Plant_Leaves_Poisoned_Red_Walkable",
      "rotation": 3
    },
    {
      "x": -13,
      "y": -7,
      "z": 9,
      "name": "Plant_Moss_Rug_Red_Placeable",
      "rotation": 3
    },
    {
      "x": -12,
      "y": -8,
      "z": 7,
      "name": "Plant_Leaves_Poisoned_Red_Walkable",
      "rotation": 3
    },
    {
      "x": -12,
      "y": -8,
      "z": 8,
      "name": "Plant_Leaves_Poisoned_Red_Walkable",
      "rotation": 3
    },
    {
      "x": -11,
      "y": -7,
      "z": 6,
      "name": "Plant_Leaves_Poisoned_Red_Walkable",
      "rotation": 3
    },
    {
      "x": -11,
      "y": -7,
      "z": 7,
      "name": "Plant_Leaves_Poisoned_Red_Walkable",
      "rotation": 3
    },
    {
      "x": -11,
      "y": -8,
      "z": 8,
      "name": "Plant_Leaves_Poisoned_Red_Walkable",
      "rotation": 3
    },
    {
      "x": -10,
      "y": -7,
      "z": 5,
      "name": "Plant_Leaves_Poisoned_Red_Walkable",
      "rotation": 3
    },
    {
      "x": -10,
      "y": -7,
      "z": 6,
      "name": "Plant_Leaves_Poisoned_Red_Walkable",
      "rotation": 3
    },
    {
      "x": -10,
      "y": -6,
      "z": 6,
      "name": "Plant_Moss_Rug_Red_Placeable",
      "rotation": 3
    },
    {
      "x": -10,
      "y": -7,
      "z": 7,
      "name": "Plant_Leaves_Poisoned_Red_Walkable",
      "rotation": 3
    },
    {
      "x": -9,
      "y": -7,
      "z": 5,
      "name": "Plant_Leaves_Poisoned_Red_Walkable",
      "rotation": 3
    },
    {
      "x": -9,
      "y": -7,
      "z": 6,
      "name": "Plant_Leaves_Poisoned_Red_Walkable",
      "rotation": 3
    },
    {
      "x": -8,
      "y": -6,
      "z": 4,
      "name": "Plant_Leaves_Poisoned_Red_Walkable",
      "rotation": 3
    },
    {
      "x": -8,
      "y": -6,
      "z": 5,
      "name": "Plant_Leaves_Poisoned_Red_Walkable",
      "rotation": 3
    },
    {
      "x": -8,
      "y": -6,
      "z": 6,
      "name": "Plant_Leaves_Poisoned_Red_Walkable",
      "rotation": 3
    },
    {
      "x": -8,
      "y": -5,
      "z": 6,
      "name": "Plant_Moss_Rug_Red_Placeable",
      "rotation": 3
    },
    {
      "x": -7,
      "y": -6,
      "z": 4,
      "name": "Plant_Leaves_Poisoned_Red_Walkable",
      "rotation": 3
    },
    {
      "x": -7,
      "y": -5,
      "z": 4,
      "name": "Plant_Moss_Rug_Red_Placeable",
      "rotation": 3
    },
    {
      "x": -7,
      "y": -6,
      "z": 5,
      "name": "Plant_Leaves_Poisoned_Red_Walkable",
      "rotation": 3
    },
    {
      "x": -6,
      "y": -5,
      "z": 3,
      "name": "Plant_Leaves_Poisoned_Red_Walkable",
      "rotation": 3
    },
    {
      "x": -6,
      "y": -4,
      "z": 3,
      "name": "Plant_Moss_Rug_Red_Placeable",
      "rotation": 3
    },
    {
      "x": -6,
      "y": -6,
      "z": 4,
      "name": "Plant_Leaves_Poisoned_Red_Walkable",
      "rotation": 3
    },
    {
      "x": -6,
      "y": -6,
      "z": 5,
      "name": "Plant_Leaves_Poisoned_Red_Walkable",
      "rotation": 3
    },
    {
      "x": -5,
      "y": -5,
      "z": 3,
      "name": "Plant_Leaves_Poisoned_Red_Walkable",
      "rotation": 3
    },
    {
      "x": -5,
      "y": -5,
      "z": 4,
      "name": "Plant_Leaves_Poisoned_Red_Walkable",
      "rotation": 3
    },
    {
      "x": -5,
      "y": -4,
      "z": 4,
      "name": "Plant_Moss_Rug_Red_Placeable",
      "rotation": 3
    },
    {
      "x": -4,
      "y": -4,
      "z": 2,
      "name": "Plant_Leaves_Poisoned_Red_Walkable",
      "rotation": 3
    },
    {
      "x": -4,
      "y": -3,
      "z": 2,
      "name": "Plant_Moss_Rug_Red_Placeable",
      "rotation": 3
    },
    {
      "x": -4,
      "y": -4,
      "z": 3,
      "name": "Plant_Leaves_Poisoned_Red_Walkable",
      "rotation": 3
    },
    {
      "x": -4,
      "y": -5,
      "z": 4,
      "name": "Plant_Leaves_Poisoned_Red_Walkable",
      "rotation": 3
    },
    {
      "x": -3,
      "y": -4,
      "z": 2,
      "name": "Plant_Leaves_Poisoned_Red_Walkable",
      "rotation": 3
    },
    {
      "x": -3,
      "y": -3,
      "z": 2,
      "name": "Plant_Moss_Rug_Red_Placeable",
      "rotation": 3
    },
    {
      "x": -3,
      "y": -4,
      "z": 3,
      "name": "Plant_Leaves_Poisoned_Red_Walkable",
      "rotation": 3
    },
    {
      "x": -3,
      "y": -3,
      "z": 3,
      "name": "Plant_Moss_Rug_Red_Placeable",
      "rotation": 3
    },
    {
      "x": -2,
      "y": -3,
      "z": 1,
      "name": "Plant_Leaves_Poisoned_Red_Walkable",
      "rotation": 3
    },
    {
      "x": -2,
      "y": -3,
      "z": 2,
      "name": "Plant_Leaves_Poisoned_Red_Walkable",
      "rotation": 3
    },
    {
      "x": -2,
      "y": -2,
      "z": 2,
      "name": "Plant_Moss_Rug_Red_Placeable",
      "rotation": 3
    },
    {
      "x": -1,
      "y": -1,
      "z": 0,
      "name": "Plant_Leaves_Poisoned_Red_Walkable",
      "rotation": 3
    },
    {
      "x": -1,
      "y": 0,
      "z": 0,
      "name": "Plant_Moss_Rug_Red_Placeable",
      "rotation": 3
    },
    {
      "x": -1,
      "y": -2,
      "z": 1,
      "name": "Plant_Leaves_Poisoned_Red_Walkable",
      "rotation": 3
    },
    {
      "x": -1,
      "y": -2,
      "z": 2,
      "name": "Plant_Leaves_Poisoned_Red_Walkable",
      "rotation": 3
    },
    {
      "x": 0,
      "y": -1,
      "z": 0,
      "name": "Plant_Leaves_Poisoned_Red_Walkable",
      "rotation": 3
    },
    {
      "x": 0,
      "y": 0,
      "z": 0,
      "name": "Plant_Leaves_Poisoned_Red_Walkable",
      "rotation": 3
    },
    {
      "x": 0,
      "y": 1,
      "z": 0,
      "name": "Plant_Moss_Rug_Red_Placeable",
      "rotation": 3
    },
    {
      "x": 0,
      "y": -1,
      "z": 1,
      "name": "Plant_Leaves_Poisoned_Red_Walkable",
      "rotation": 3
    },
    {
      "x": 0,
      "y": 0,
      "z": 1,
      "name": "Plant_Moss_Rug_Red_Placeable",
      "rotation": 3
    }
  ]
}