{
  "version": 8,
  "blockIdVersion": 11,
  "anchorX": 0,
  "anchorY": 0,
  "anchorZ": 0,
  "blocks": [
    {
      "x": -1,
      "y": -1,
      "z": 0,
      "name": "Wood_Crystal_Trunk_Full",
      "support": 15
    },
    {
      "x": -1,
      "y": 0,
      "z": 0,
      "name": "Wood_Crystal_Trunk_Full"
    },
    {
      "x": -1,
      "y": 1,
      "z": 0,
      "name": "Wood_Crystal_Trunk_Full",
      "support": 15
    },
    {
      "x": -1,
      "y": 0,
      "z": 1,
      "name": "Wood_Crystal_Trunk_Full",
      "support": 15
    },
    {
      "x": -1,
      "y": 1,
      "z": 1,
      "name": "Wood_Crystal_Trunk_Full",
      "support": 15
    },
    {
      "x": -1,
      "y": 2,
      "z": 1,
      "name": "Wood_Crystal_Trunk_Full",
      "support": 15
    },
    {
      "x": 0,
      "y": 0,
      "z": -1,
      "name": "Wood_Crystal_Trunk_Full"
    },
    {
      "x": 0,
      "y": 7,
      "z": -1,
      "name": "Wood_Crystal_Trunk_Full",
      "support": 15
    },
    {
      "x": 0,
      "y": 8,
      "z": -1,
      "name": "Wood_Crystal_Trunk_Full"
    },
    {
      "x": 0,
      "y": -1,
      "z": 0,
      "name": "Wood_Crystal_Trunk_Full"
    },
    {
      "x": 0,
      "y": 0,
      "z": 0,
      "name": "Wood_Crystal_Trunk_Full"
    },
    {
      "x": 0,
      "y": 1,
      "z": 0,
      "name": "Wood_Crystal_Trunk_Full"
    },
    {
      "x": 0,
      "y": 2,
      "z": 0,
      "name": "Wood_Crystal_Trunk_Full"
    },
    {
      "x": 0,
      "y": 4,
      "z": 0,
      "name": "Wood_Crystal_Trunk_Full"
    },
    {
      "x": 0,
      "y": 5,
      "z": 0,
      "name": "Wood_Crystal_Trunk_Full",
      "support": 15
    },
    {
      "x": 0,
      "y": 6,
      "z": 0,
      "name": "Wood_Crystal_Trunk_Full"
    },
    {
      "x": 0,
      "y": -1,
      "z": 1,
      "name": "Wood_Crystal_Trunk_Full"
    },
    {
      "x": 0,
      "y": 0,
      "z": 1,
      "name": "Wood_Crystal_Trunk_Full"
    },
    {
      "x": 0,
      "y": 1,
      "z": 1,
      "name": "Wood_Crystal_Trunk_Full"
    },
    {
      "x": 0,
      "y": 2,
      "z": 1,
      "name": "Wood_Crystal_Trunk_Full",
      "support": 15
    },
    {
      "x": 0,
      "y": 3,
      "z": 1,
      "name": "Wood_Crystal_Trunk_Full"
    },
    {
      "x": 1,
      "y": 2,
      "z": -1,
      "name": "Wood_Crystal_Trunk_Full"
    },
    {
      "x": 1,
      "y": 3,
      "z": -1,
      "name": "Wood_Crystal_Trunk_Full",
      "support": 15
    },
    {
      "x": 1,
      "y": 7,
      "z": -1,
      "name": "Wood_Crystal_Trunk_Full"
    },
    {
      "x": 1,
      "y": 8,
      "z": -1,
      "name": "Wood_Crystal_Trunk_Full"
    },
    {
      "x": 1,
      "y": 9,
      "z": -1,
      "name": "Wood_Crystal_Trunk_Full"
    },
    {
      "x": 1,
      "y": 0,
      "z": 0,
      "name": "Wood_Crystal_Trunk_Full"
    },
    {
      "x": 1,
      "y": 1,
      "z": 0,
      "name": "Wood_Crystal_Trunk_Full"
    },
    {
      "x": 1,
      "y": 2,
      "z": 0,
      "name": "Wood_Crystal_Trunk_Full"
    },
    {
      "x": 1,
      "y": 3,
      "z": 0,
      "name": "Wood_Crystal_Trunk_Full"
    },
    {
      "x": 1,
      "y": 4,
      "z": 0,
      "name": "Wood_Crystal_Trunk_Full"
    },
    {
      "x": 1,
      "y": 5,
      "z": 0,
      "name": "Wood_Crystal_Trunk_Full"
    },
    {
      "x": 1,
      "y": 6,
      "z": 0,
      "name": "Wood_Crystal_Trunk_Full"
    },
    {
      "x": 1,
      "y": 7,
      "z": 0,
      "name": "Wood_Crystal_Trunk_Full",
      "support": 15
    },
    {
      "x": 1,
      "y": 8,
      "z": 0,
      "name": "Wood_Crystal_Trunk_Full"
    },
    {
      "x": 1,
      "y": 9,
      "z": 0,
      "name": "Wood_Crystal_Trunk_Full"
    },
    {
      "x": 1,
      "y": 10,
      "z": 0,
      "name": "Wood_Crystal_Trunk_Full"
    },
    {
      "x": 1,
      "y": 0,
      "z": 1,
      "name": "Wood_Crystal_Trunk_Full"
    },
    {
      "x": 1,
      "y": 1,
      "z": 1,
      "name": "Wood_Crystal_Trunk_Full"
    },
    {
      "x": 1,
      "y": 2,
      "z": 1,
      "name": "Wood_Crystal_Trunk_Full"
    },
    {
      "x": 1,
      "y": 3,
      "z": 1,
      "name": "Wood_Crystal_Trunk_Full"
    },
    {
      "x": 1,
      "y": 4,
      "z": 1,
      "name": "Wood_Crystal_Trunk_Full"
    },
    {
      "x": 1,
      "y": 6,
      "z": 1,
      "name": "Wood_Crystal_Trunk_Full"
    },
    {
      "x": 1,
      "y": 8,
      "z": 1,
      "name": "Wood_Crystal_Trunk_Full"
    },
    {
      "x": 1,
      "y": 9,
      "z": 1,
      "name": "Wood_Crystal_Trunk_Full"
    },
    {
      "x": 1,
      "y": 3,
      "z": 2,
      "name": "Wood_Crystal_Trunk_Full"
    },
    {
      "x": 2,
      "y": 10,
      "z": -2,
      "name": "Wood_Crystal_Trunk_Full",
      "support": 15,
      "rotation": 5
    },
    {
      "x": 2,
      "y": 8,
      "z": -1,
      "name": "Wood_Crystal_Trunk_Full"
    },
    {
      "x": 2,
      "y": 10,
      "z": -1,
      "name": "Wood_Crystal_Trunk_Full"
    },
    {
      "x": 2,
      "y": 11,
      "z": -1,
      "name": "Wood_Crystal_Trunk_Full"
    },
    {
      "x": 2,
      "y": 12,
      "z": -1,
      "name": "Wood_Crystal_Trunk_Full"
    },
    {
      "x": 2,
      "y": 2,
      "z": 0,
      "name": "Wood_Crystal_Trunk_Full"
    },
    {
      "x": 2,
      "y": 4,
      "z": 0,
      "name": "Wood_Crystal_Trunk_Full"
    },
    {
      "x": 2,
      "y": 6,
      "z": 0,
      "name": "Wood_Crystal_Trunk_Full"
    },
    {
      "x": 2,
      "y": 7,
      "z": 0,
      "name": "Wood_Crystal_Trunk_Full",
      "support": 15
    },
    {
      "x": 2,
      "y": 8,
      "z": 0,
      "name": "Wood_Crystal_Trunk_Full",
      "support": 15,
      "rotation": 4
    },
    {
      "x": 2,
      "y": 9,
      "z": 0,
      "name": "Wood_Crystal_Trunk_Full"
    },
    {
      "x": 2,
      "y": 10,
      "z": 0,
      "name": "Wood_Crystal_Trunk_Full"
    },
    {
      "x": 2,
      "y": 11,
      "z": 0,
      "name": "Wood_Crystal_Trunk_Full"
    },
    {
      "x": 2,
      "y": 12,
      "z": 0,
      "name": "Wood_Crystal_Trunk_Full",
      "support": 15
    },
    {
      "x": 2,
      "y": 1,
      "z": 1,
      "name": "Wood_Crystal_Trunk_Full"
    },
    {
      "x": 2,
      "y": 3,
      "z": 1,
      "name": "Wood_Crystal_Trunk_Full"
    },
    {
      "x": 2,
      "y": 4,
      "z": 1,
      "name": "Wood_Crystal_Trunk_Full"
    },
    {
      "x": 2,
      "y": 5,
      "z": 1,
      "name": "Wood_Crystal_Trunk_Full"
    },
    {
      "x": 2,
      "y": 6,
      "z": 1,
      "name": "Wood_Crystal_Trunk_Full"
    },
    {
      "x": 2,
      "y": 7,
      "z": 1,
      "name": "Wood_Crystal_Trunk_Full"
    },
    {
      "x": 2,
      "y": 8,
      "z": 1,
      "name": "Wood_Crystal_Trunk_Full",
      "support": 15
    },
    {
      "x": 2,
      "y": 9,
      "z": 1,
      "name": "Wood_Crystal_Trunk_Full"
    },
    {
      "x": 2,
      "y": 10,
      "z": 1,
      "name": "Wood_Crystal_Trunk_Full"
    },
    {
      "x": 2,
      "y": 4,
      "z": 2,
      "name": "Wood_Crystal_Trunk_Full"
    },
    {
      "x": 2,
      "y": 5,
      "z": 2,
      "name": "Wood_Crystal_Trunk_Full",
      "support": 15
    },
    {
      "x": 2,
      "y": 6,
      "z": 2,
      "name": "Wood_Crystal_Trunk_Full"
    },
    {
      "x": 3,
      "y": 10,
      "z": -2,
      "name": "Wood_Crystal_Trunk_Full",
      "support": 15,
      "rotation": 4
    },
    {
      "x": 3,
      "y": 11,
      "z": -2,
      "name": "Wood_Crystal_Trunk_Full"
    },
    {
      "x": 3,
      "y": 12,
      "z": -2,
      "name": "Wood_Crystal_Trunk_Full"
    },
    {
      "x": 3,
      "y": 9,
      "z": -1,
      "name": "Wood_Crystal_Trunk_Full"
    },
    {
      "x": 3,
      "y": 10,
      "z": -1,
      "name": "Wood_Crystal_Trunk_Full"
    },
    {
      "x": 3,
      "y": 11,
      "z": -1,
      "name": "Wood_Crystal_Trunk_Full"
    },
    {
      "x": 3,
      "y": 12,
      "z": -1,
      "name": "Wood_Crystal_Trunk_Full"
    },
    {
      "x": 3,
      "y": 13,
      "z": -1,
      "name": "Wood_Crystal_Trunk_Full"
    },
    {
      "x": 3,
      "y": 9,
      "z": 0,
      "name": "Wood_Crystal_Trunk_Full",
      "support": 15,
      "rotation": 5
    },
    {
      "x": 3,
      "y": 10,
      "z": 0,
      "name": "Wood_Crystal_Trunk_Full"
    },
    {
      "x": 3,
      "y": 11,
      "z": 0,
      "name": "Wood_Crystal_Trunk_Full"
    },
    {
      "x": 3,
      "y": 12,
      "z": 0,
      "name": "Wood_Crystal_Trunk_Full"
    },
    {
      "x": 3,
      "y": 5,
      "z": 1,
      "name": "Wood_Crystal_Trunk_Full"
    },
    {
      "x": 3,
      "y": 6,
      "z": 1,
      "name": "Wood_Crystal_Trunk_Full"
    },
    {
      "x": 3,
      "y": 10,
      "z": 1,
      "name": "Wood_Crystal_Trunk_Full"
    },
    {
      "x": 3,
      "y": 11,
      "z": 1,
      "name": "Wood_Crystal_Trunk_Full",
      "support": 15
    },
    {
      "x": 3,
      "y": 7,
      "z": 2,
      "name": "Wood_Crystal_Trunk_Full"
    },
    {
      "x": 4,
      "y": 11,
      "z": -2,
      "name": "Wood_Crystal_Trunk_Full",
      "support": 15,
      "rotation": 4
    },
    {
      "x": 4,
      "y": 12,
      "z": -2,
      "name": "Wood_Crystal_Trunk_Full",
      "support": 15
    },
    {
      "x": 4,
      "y": 10,
      "z": -1,
      "name": "Wood_Crystal_Trunk_Full"
    },
    {
      "x": 4,
      "y": 11,
      "z": -1,
      "name": "Wood_Crystal_Trunk_Full"
    },
    {
      "x": 4,
      "y": 10,
      "z": 0,
      "name": "Wood_Crystal_Trunk_Full"
    }
  ]
}