{
  "version": 8,
  "blockIdVersion": 11,
  "anchorX": 0,
  "anchorY": 0,
  "anchorZ": 0,
  "blocks": [
    {
      "x": -1,
      "y": 1,
      "z": -1,
      "name": "Wood_Crystal_Trunk_Full"
    },
    {
      "x": -1,
      "y": 1,
      "z": 1,
      "name": "Wood_Crystal_Trunk_Full"
    },
    {
      "x": -1,
      "y": 0,
      "z": 2,
      "name": "Wood_Crystal_Trunk_Full"
    },
    {
      "x": -1,
      "y": 0,
      "z": 3,
      "name": "Wood_Crystal_Trunk_Full"
    },
    {
      "x": -1,
      "y": -1,
      "z": 4,
      "name": "Wood_Crystal_Trunk_Full"
    },
    {
      "x": -1,
      "y": 0,
      "z": 4,
      "name": "Wood_Crystal_Trunk_Full"
    },
    {
      "x": -1,
      "y": -2,
      "z": 5,
      "name": "Wood_Crystal_Trunk_Full"
    },
    {
      "x": 0,
      "y": 0,
      "z": -1,
      "name": "Wood_Crystal_Trunk_Full"
    },
    {
      "x": 0,
      "y": 1,
      "z": -1,
      "name": "Wood_Crystal_Trunk_Full"
    },
    {
      "x": 0,
      "y": 2,
      "z": -1,
      "name": "Wood_Crystal_Trunk_Full"
    },
    {
      "x": 0,
      "y": 0,
      "z": 0,
      "name": "Wood_Crystal_Trunk_Full"
    },
    {
      "x": 0,
      "y": 1,
      "z": 0,
      "name": "Wood_Crystal_Trunk_Full"
    },
    {
      "x": 0,
      "y": 2,
      "z": 0,
      "name": "Wood_Crystal_Trunk_Full",
      "support": 15
    },
    {
      "x": 0,
      "y": 1,
      "z": 1,
      "name": "Wood_Crystal_Trunk_Full"
    },
    {
      "x": 0,
      "y": 2,
      "z": 1,
      "name": "Wood_Crystal_Trunk_Full"
    },
    {
      "x": 0,
      "y": 0,
      "z": 2,
      "name": "Wood_Crystal_Trunk_Full"
    },
    {
      "x": 0,
      "y": 1,
      "z": 2,
      "name": "Wood_Crystal_Trunk_Full"
    },
    {
      "x": 0,
      "y": -1,
      "z": 3,
      "name": "Wood_Crystal_Trunk_Full"
    },
    {
      "x": 0,
      "y": 0,
      "z": 3,
      "name": "Wood_Crystal_Trunk_Full"
    },
    {
      "x": 0,
      "y": 1,
      "z": 3,
      "name": "Wood_Crystal_Trunk_Full"
    },
    {
      "x": 0,
      "y": -2,
      "z": 4,
      "name": "Wood_Crystal_Trunk_Full"
    },
    {
      "x": 0,
      "y": -1,
      "z": 4,
      "name": "Wood_Crystal_Trunk_Full"
    },
    {
      "x": 0,
      "y": 0,
      "z": 4,
      "name": "Wood_Crystal_Trunk_Full"
    },
    {
      "x": 0,
      "y": -3,
      "z": 5,
      "name": "Wood_Crystal_Trunk_Full"
    },
    {
      "x": 0,
      "y": -2,
      "z": 5,
      "name": "Wood_Crystal_Trunk_Full"
    },
    {
      "x": 0,
      "y": -1,
      "z": 5,
      "name": "Wood_Crystal_Trunk_Full"
    },
    {
      "x": 0,
      "y": -4,
      "z": 6,
      "name": "Wood_Crystal_Trunk_Full",
      "support": 15
    },
    {
      "x": 0,
      "y": -3,
      "z": 6,
      "name": "Wood_Crystal_Trunk_Full",
      "support": 15
    },
    {
      "x": 0,
      "y": -2,
      "z": 6,
      "name": "Wood_Crystal_Trunk_Full"
    },
    {
      "x": 0,
      "y": -4,
      "z": 7,
      "name": "Wood_Crystal_Trunk_Full",
      "support": 15
    },
    {
      "x": 1,
      "y": 0,
      "z": -1,
      "name": "Wood_Crystal_Trunk_Full"
    },
    {
      "x": 1,
      "y": 1,
      "z": -1,
      "name": "Wood_Crystal_Trunk_Full"
    },
    {
      "x": 1,
      "y": 2,
      "z": -1,
      "name": "Wood_Crystal_Trunk_Full"
    },
    {
      "x": 1,
      "y": 0,
      "z": 0,
      "name": "Wood_Crystal_Trunk_Full"
    },
    {
      "x": 1,
      "y": 1,
      "z": 0,
      "name": "Wood_Crystal_Trunk_Full"
    },
    {
      "x": 1,
      "y": 2,
      "z": 0,
      "name": "Wood_Crystal_Trunk_Full"
    },
    {
      "x": 1,
      "y": 0,
      "z": 1,
      "name": "Wood_Crystal_Trunk_Full"
    },
    {
      "x": 1,
      "y": 1,
      "z": 1,
      "name": "Wood_Crystal_Trunk_Full"
    },
    {
      "x": 1,
      "y": 2,
      "z": 1,
      "name": "Wood_Crystal_Trunk_Full"
    },
    {
      "x": 1,
      "y": 0,
      "z": 2,
      "name": "Wood_Crystal_Trunk_Full",
      "support": 15
    },
    {
      "x": 1,
      "y": 1,
      "z": 2,
      "name": "Wood_Crystal_Trunk_Full"
    },
    {
      "x": 1,
      "y": 2,
      "z": 2,
      "name": "Wood_Crystal_Trunk_Full"
    },
    {
      "x": 1,
      "y": 0,
      "z": 3,
      "name": "Wood_Crystal_Trunk_Full"
    },
    {
      "x": 1,
      "y": 1,
      "z": 3,
      "name": "Wood_Crystal_Trunk_Full"
    },
    {
      "x": 1,
      "y": -1,
      "z": 4,
      "name": "Wood_Crystal_Trunk_Full"
    },
    {
      "x": 1,
      "y": -2,
      "z": 5,
      "name": "Wood_Crystal_Trunk_Full"
    },
    {
      "x": 1,
      "y": -1,
      "z": 5,
      "name": "Wood_Crystal_Trunk_Full"
    },
    {
      "x": 2,
      "y": 1,
      "z": -1,
      "name": "Wood_Crystal_Trunk_Full"
    },
    {
      "x": 2,
      "y": 1,
      "z": 0,
      "name": "Wood_Crystal_Trunk_Full"
    }
  ]
}