{
  "version": 8,
  "blockIdVersion": 11,
  "anchorX": 0,
  "anchorY": 0,
  "anchorZ": 0,
  "blocks": [
    {
      "x": -1,
      "y": 0,
      "z": -1,
      "name": "Wood_Crystal_Trunk_Full",
      "support": 15,
      "rotation": 5
    },
    {
      "x": -1,
      "y": -1,
      "z": 0,
      "name": "Wood_Crystal_Trunk_Full",
      "support": 15,
      "rotation": 5
    },
    {
      "x": -1,
      "y": 0,
      "z": 0,
      "name": "Wood_Crystal_Trunk_Full",
      "support": 15,
      "rotation": 5
    },
    {
      "x": -1,
      "y": 0,
      "z": 1,
      "name": "Wood_Crystal_Trunk_Full",
      "support": 15,
      "rotation": 5
    },
    {
      "x": 0,
      "y": 0,
      "z": -1,
      "name": "Wood_Crystal_Trunk_Full",
      "support": 15,
      "rotation": 5
    },
    {
      "x": 0,
      "y": 0,
      "z": 0,
      "name": "Wood_Crystal_Trunk_Full",
      "support": 15,
      "rotation": 5
    },
    {
      "x": 0,
      "y": 1,
      "z": 0,
      "name": "Wood_Crystal_Trunk_Full",
      "support": 15,
      "rotation": 5
    },
    {
      "x": 1,
      "y": 0,
      "z": 0,
      "name": "Wood_Crystal_Trunk_Full",
      "support": 15
    },
    {
      "x": 1,
      "y": 1,
      "z": 0,
      "name": "Wood_Crystal_Trunk_Full",
      "support": 15,
      "rotation": 5
    },
    {
      "x": 1,
      "y": 3,
      "z": 3,
      "name": "Plant_Leaves_Crystal",
      "support": 15
    },
    {
      "x": 1,
      "y": 2,
      "z": 5,
      "name": "Plant_Leaves_Crystal",
      "support": 15
    },
    {
      "x": 2,
      "y": 3,
      "z": -2,
      "name": "Plant_Leaves_Crystal",
      "support": 15
    },
    {
      "x": 2,
      "y": 1,
      "z": -1,
      "name": "Plant_Leaves_Crystal",
      "support": 15
    },
    {
      "x": 2,
      "y": 1,
      "z": 0,
      "name": "Wood_Crystal_Trunk_Full",
      "support": 15,
      "rotation": 5
    },
    {
      "x": 2,
      "y": 2,
      "z": 0,
      "name": "Wood_Crystal_Trunk_Full",
      "support": 15
    },
    {
      "x": 2,
      "y": 2,
      "z": 1,
      "name": "Wood_Crystal_Trunk_Full",
      "support": 15,
      "rotation": 4
    },
    {
      "x": 2,
      "y": 3,
      "z": 1,
      "name": "Plant_Leaves_Crystal",
      "support": 15
    },
    {
      "x": 2,
      "y": 2,
      "z": 2,
      "name": "Wood_Crystal_Trunk_Full",
      "support": 15,
      "rotation": 4
    },
    {
      "x": 2,
      "y": 3,
      "z": 2,
      "name": "Wood_Crystal_Trunk_Full",
      "support": 15
    },
    {
      "x": 2,
      "y": 2,
      "z": 3,
      "name": "Plant_Leaves_Crystal",
      "support": 15
    },
    {
      "x": 2,
      "y": 3,
      "z": 3,
      "name": "Wood_Crystal_Trunk_Full",
      "support": 15,
      "rotation": 4
    },
    {
      "x": 2,
      "y": 2,
      "z": 4,
      "name": "Wood_Crystal_Trunk_Full",
      "support": 15
    },
    {
      "x": 2,
      "y": 3,
      "z": 4,
      "name": "Wood_Crystal_Trunk_Full",
      "support": 15,
      "rotation": 4
    },
    {
      "x": 2,
      "y": 4,
      "z": 4,
      "name": "Plant_Leaves_Crystal",
      "support": 15
    },
    {
      "x": 2,
      "y": 2,
      "z": 5,
      "name": "Wood_Crystal_Trunk_Full",
      "support": 15,
      "rotation": 4
    },
    {
      "x": 2,
      "y": 3,
      "z": 5,
      "name": "Plant_Leaves_Crystal",
      "support": 15
    },
    {
      "x": 2,
      "y": 2,
      "z": 6,
      "name": "Plant_Leaves_Crystal",
      "support": 15
    },
    {
      "x": 2,
      "y": 3,
      "z": 6,
      "name": "Plant_Leaves_Crystal",
      "support": 15
    },
    {
      "x": 3,
      "y": 3,
      "z": -3,
      "name": "Plant_Leaves_Crystal",
      "support": 15
    },
    {
      "x": 3,
      "y": 2,
      "z": -2,
      "name": "Wood_Crystal_Trunk_Full",
      "support": 15,
      "rotation": 4
    },
    {
      "x": 3,
      "y": 3,
      "z": -2,
      "name": "Wood_Crystal_Trunk_Full",
      "support": 15
    },
    {
      "x": 3,
      "y": 1,
      "z": -1,
      "name": "Plant_Leaves_Crystal",
      "support": 15
    },
    {
      "x": 3,
      "y": 2,
      "z": -1,
      "name": "Wood_Crystal_Trunk_Full",
      "support": 15,
      "rotation": 4
    },
    {
      "x": 3,
      "y": 0,
      "z": 0,
      "name": "Plant_Leaves_Crystal",
      "support": 15
    },
    {
      "x": 3,
      "y": 1,
      "z": 0,
      "name": "Wood_Crystal_Trunk_Full",
      "support": 15,
      "rotation": 5
    },
    {
      "x": 3,
      "y": 2,
      "z": 0,
      "name": "Wood_Crystal_Trunk_Full",
      "support": 15,
      "rotation": 5
    },
    {
      "x": 3,
      "y": 3,
      "z": 2,
      "name": "Plant_Leaves_Crystal",
      "support": 15
    },
    {
      "x": 3,
      "y": 2,
      "z": 3,
      "name": "Plant_Leaves_Crystal",
      "support": 15
    },
    {
      "x": 3,
      "y": 3,
      "z": 3,
      "name": "Wood_Crystal_Trunk_Full",
      "support": 15,
      "rotation": 5
    },
    {
      "x": 3,
      "y": 4,
      "z": 3,
      "name": "Plant_Leaves_Crystal",
      "support": 15
    },
    {
      "x": 3,
      "y": 2,
      "z": 4,
      "name": "Plant_Fruit_Pinkberry"
    },
    {
      "x": 3,
      "y": 3,
      "z": 4,
      "name": "Plant_Leaves_Crystal",
      "support": 15
    },
    {
      "x": 3,
      "y": 4,
      "z": 4,
      "name": "Plant_Leaves_Crystal",
      "support": 15
    },
    {
      "x": 3,
      "y": 1,
      "z": 5,
      "name": "Plant_Leaves_Crystal",
      "support": 15
    },
    {
      "x": 3,
      "y": 2,
      "z": 5,
      "name": "Wood_Crystal_Trunk_Full",
      "support": 15,
      "rotation": 5
    },
    {
      "x": 3,
      "y": 3,
      "z": 5,
      "name": "Wood_Crystal_Trunk_Full",
      "support": 15
    },
    {
      "x": 4,
      "y": 3,
      "z": -4,
      "name": "Plant_Leaves_Crystal",
      "support": 15
    },
    {
      "x": 4,
      "y": 2,
      "z": -3,
      "name": "Plant_Leaves_Crystal",
      "support": 15
    },
    {
      "x": 4,
      "y": 3,
      "z": -3,
      "name": "Wood_Crystal_Trunk_Full",
      "support": 15,
      "rotation": 4
    },
    {
      "x": 4,
      "y": 4,
      "z": -3,
      "name": "Plant_Leaves_Crystal",
      "support": 15
    },
    {
      "x": 4,
      "y": 2,
      "z": -2,
      "name": "Plant_Leaves_Crystal",
      "support": 15
    },
    {
      "x": 4,
      "y": 3,
      "z": -2,
      "name": "Wood_Crystal_Trunk_Full",
      "support": 15,
      "rotation": 5
    },
    {
      "x": 4,
      "y": 4,
      "z": -2,
      "name": "Plant_Leaves_Crystal",
      "support": 15
    },
    {
      "x": 4,
      "y": 1,
      "z": 0,
      "name": "Wood_Crystal_Trunk_Full",
      "support": 15
    },
    {
      "x": 4,
      "y": 2,
      "z": 0,
      "name": "Wood_Crystal_Trunk_Full",
      "support": 15,
      "rotation": 5
    },
    {
      "x": 4,
      "y": 3,
      "z": 0,
      "name": "Plant_Leaves_Crystal",
      "support": 15
    },
    {
      "x": 4,
      "y": 3,
      "z": 3,
      "name": "Plant_Leaves_Crystal",
      "support": 15
    },
    {
      "x": 4,
      "y": 4,
      "z": 3,
      "name": "Plant_Leaves_Crystal",
      "support": 15
    },
    {
      "x": 4,
      "y": 3,
      "z": 5,
      "name": "Wood_Crystal_Trunk_Full",
      "support": 15,
      "rotation": 5
    },
    {
      "x": 4,
      "y": 4,
      "z": 5,
      "name": "Plant_Leaves_Crystal",
      "support": 15
    },
    {
      "x": 4,
      "y": 3,
      "z": 6,
      "name": "Plant_Leaves_Crystal",
      "support": 15
    },
    {
      "x": 5,
      "y": 3,
      "z": -3,
      "name": "Plant_Leaves_Crystal",
      "support": 15
    },
    {
      "x": 5,
      "y": 3,
      "z": -2,
      "name": "Plant_Leaves_Crystal",
      "support": 15
    },
    {
      "x": 5,
      "y": 2,
      "z": -1,
      "name": "Plant_Leaves_Crystal",
      "support": 15
    },
    {
      "x": 5,
      "y": 1,
      "z": 0,
      "name": "Plant_Leaves_Crystal",
      "support": 15
    },
    {
      "x": 5,
      "y": 2,
      "z": 0,
      "name": "Wood_Crystal_Trunk_Full",
      "support": 15,
      "rotation": 5
    },
    {
      "x": 5,
      "y": 3,
      "z": 0,
      "name": "Wood_Crystal_Trunk_Full",
      "support": 15
    },
    {
      "x": 5,
      "y": 2,
      "z": 5,
      "name": "Plant_Leaves_Crystal",
      "support": 15
    },
    {
      "x": 5,
      "y": 3,
      "z": 5,
      "name": "Plant_Leaves_Crystal",
      "support": 15
    },
    {
      "x": 6,
      "y": 2,
      "z": -1,
      "name": "Plant_Fruit_Pinkberry",
      "rotation": 8
    },
    {
      "x": 6,
      "y": 3,
      "z": -1,
      "name": "Plant_Leaves_Crystal",
      "support": 15
    },
    {
      "x": 6,
      "y": 2,
      "z": 0,
      "name": "Plant_Leaves_Crystal",
      "support": 15
    },
    {
      "x": 6,
      "y": 3,
      "z": 0,
      "name": "Wood_Crystal_Trunk_Full",
      "support": 15,
      "rotation": 5
    },
    {
      "x": 6,
      "y": 3,
      "z": 1,
      "name": "Wood_Crystal_Trunk_Full",
      "support": 15,
      "rotation": 4
    },
    {
      "x": 6,
      "y": 4,
      "z": 1,
      "name": "Plant_Leaves_Crystal",
      "support": 15
    },
    {
      "x": 6,
      "y": 2,
      "z": 2,
      "name": "Plant_Leaves_Crystal",
      "support": 15
    },
    {
      "x": 6,
      "y": 3,
      "z": 2,
      "name": "Wood_Crystal_Trunk_Full",
      "support": 15,
      "rotation": 4
    },
    {
      "x": 6,
      "y": 4,
      "z": 2,
      "name": "Plant_Leaves_Crystal",
      "support": 15
    },
    {
      "x": 6,
      "y": 3,
      "z": 3,
      "name": "Plant_Leaves_Crystal",
      "support": 15
    },
    {
      "x": 7,
      "y": 3,
      "z": -1,
      "name": "Plant_Leaves_Crystal",
      "support": 15
    },
    {
      "x": 7,
      "y": 4,
      "z": -1,
      "name": "Plant_Leaves_Crystal",
      "support": 15
    },
    {
      "x": 7,
      "y": 2,
      "z": 0,
      "name": "Plant_Leaves_Crystal",
      "support": 15
    },
    {
      "x": 7,
      "y": 3,
      "z": 0,
      "name": "Wood_Crystal_Trunk_Full",
      "support": 15,
      "rotation": 5
    },
    {
      "x": 7,
      "y": 4,
      "z": 0,
      "name": "Plant_Leaves_Crystal",
      "support": 15
    },
    {
      "x": 7,
      "y": 3,
      "z": 1,
      "name": "Plant_Leaves_Crystal",
      "support": 15
    },
    {
      "x": 7,
      "y": 2,
      "z": 2,
      "name": "Plant_Fruit_Pinkberry",
      "rotation": 8
    },
    {
      "x": 7,
      "y": 3,
      "z": 2,
      "name": "Plant_Leaves_Crystal",
      "support": 15
    },
    {
      "x": 7,
      "y": 4,
      "z": 2,
      "name": "Plant_Leaves_Crystal",
      "support": 15
    },
    {
      "x": 8,
      "y": 2,
      "z": 0,
      "name": "Plant_Leaves_Crystal",
      "support": 15
    },
    {
      "x": 8,
      "y": 3,
      "z": 0,
      "name": "Plant_Leaves_Crystal",
      "support": 15
    },
    {
      "x": 8,
      "y": 3,
      "z": 1,
      "name": "Plant_Leaves_Crystal",
      "support": 15
    }
  ]
}